[2024-05-09T08:17:53.034+0000] {local_task_job_runner.py:120} INFO - ::group::Pre task execution logs
[2024-05-09T08:17:53.072+0000] {taskinstance.py:2076} INFO - Dependencies all met for dep_context=non-requeueable deps ti=<TaskInstance: weather_dag.is_weater_api_ready manual__2024-05-09T08:13:17.673871+00:00 [queued]>
[2024-05-09T08:17:53.082+0000] {taskinstance.py:2076} INFO - Dependencies all met for dep_context=requeueable deps ti=<TaskInstance: weather_dag.is_weater_api_ready manual__2024-05-09T08:13:17.673871+00:00 [queued]>
[2024-05-09T08:17:53.083+0000] {taskinstance.py:2306} INFO - Starting attempt 3 of 3
[2024-05-09T08:17:53.138+0000] {taskinstance.py:2330} INFO - Executing <Task(HttpSensor): is_weater_api_ready> on 2024-05-09 08:13:17.673871+00:00
[2024-05-09T08:17:53.144+0000] {standard_task_runner.py:63} INFO - Started process 22850 to run task
[2024-05-09T08:17:53.154+0000] {standard_task_runner.py:90} INFO - Running: ['airflow', 'tasks', 'run', 'weather_dag', 'is_weater_api_ready', 'manual__2024-05-09T08:13:17.673871+00:00', '--job-id', '12', '--raw', '--subdir', 'DAGS_FOLDER/weather_dag.py', '--cfg-path', '/tmp/tmp72cnp92p']
[2024-05-09T08:17:53.158+0000] {standard_task_runner.py:91} INFO - Job 12: Subtask is_weater_api_ready
[2024-05-09T08:17:53.258+0000] {task_command.py:426} INFO - Running <TaskInstance: weather_dag.is_weater_api_ready manual__2024-05-09T08:13:17.673871+00:00 [running]> on host ubuntu2204
[2024-05-09T08:17:53.404+0000] {taskinstance.py:2648} INFO - Exporting env vars: AIRFLOW_CTX_DAG_EMAIL='test@gmail.com' AIRFLOW_CTX_DAG_OWNER='airflow' AIRFLOW_CTX_DAG_ID='weather_dag' AIRFLOW_CTX_TASK_ID='is_weater_api_ready' AIRFLOW_CTX_EXECUTION_DATE='2024-05-09T08:13:17.673871+00:00' AIRFLOW_CTX_TRY_NUMBER='3' AIRFLOW_CTX_DAG_RUN_ID='manual__2024-05-09T08:13:17.673871+00:00'
[2024-05-09T08:17:53.409+0000] {taskinstance.py:430} INFO - ::endgroup::
[2024-05-09T08:17:53.410+0000] {baseoperator.py:399} WARNING - HttpSensor.execute cannot be called outside TaskInstance!
[2024-05-09T08:17:53.412+0000] {http.py:137} INFO - Poking: /data/2.5/weather?q=Kyiv&appid=a2fc2ab52b832be75e0040a88f3e406a
[2024-05-09T08:17:53.435+0000] {base.py:84} INFO - Using connection ID 'weathermap_api' for task execution.
[2024-05-09T08:17:53.770+0000] {http.py:200} ERROR - HTTP error: Unauthorized
[2024-05-09T08:17:53.771+0000] {http.py:201} ERROR - {"cod":401, "message": "Invalid API key. Please see https://openweathermap.org/faq#error401 for more info."}
[2024-05-09T08:17:53.771+0000] {taskinstance.py:441} INFO - ::group::Post task execution logs
[2024-05-09T08:17:53.780+0000] {taskinstance.py:2905} ERROR - Task failed with exception
Traceback (most recent call last):
  File "/home/denys/airflow_venv/lib/python3.12/site-packages/airflow/providers/http/hooks/http.py", line 198, in check_response
    response.raise_for_status()
  File "/home/denys/airflow_venv/lib/python3.12/site-packages/requests/models.py", line 1021, in raise_for_status
    raise HTTPError(http_error_msg, response=self)
requests.exceptions.HTTPError: 401 Client Error: Unauthorized for url: http://api.openweathermap.org/data/2.5/weather?q=Kyiv&appid=a2fc2ab52b832be75e0040a88f3e406a

During handling of the above exception, another exception occurred:

Traceback (most recent call last):
  File "/home/denys/airflow_venv/lib/python3.12/site-packages/airflow/models/taskinstance.py", line 465, in _execute_task
    result = _execute_callable(context=context, **execute_callable_kwargs)
             ^^^^^^^^^^^^^^^^^^^^^^^^^^^^^^^^^^^^^^^^^^^^^^^^^^^^^^^^^^^^^
  File "/home/denys/airflow_venv/lib/python3.12/site-packages/airflow/models/taskinstance.py", line 432, in _execute_callable
    return execute_callable(context=context, **execute_callable_kwargs)
           ^^^^^^^^^^^^^^^^^^^^^^^^^^^^^^^^^^^^^^^^^^^^^^^^^^^^^^^^^^^^
  File "/home/denys/airflow_venv/lib/python3.12/site-packages/airflow/models/baseoperator.py", line 400, in wrapper
    return func(self, *args, **kwargs)
           ^^^^^^^^^^^^^^^^^^^^^^^^^^^
  File "/home/denys/airflow_venv/lib/python3.12/site-packages/airflow/providers/http/sensors/http.py", line 164, in execute
    super().execute(context=context)
  File "/home/denys/airflow_venv/lib/python3.12/site-packages/airflow/models/baseoperator.py", line 400, in wrapper
    return func(self, *args, **kwargs)
           ^^^^^^^^^^^^^^^^^^^^^^^^^^^
  File "/home/denys/airflow_venv/lib/python3.12/site-packages/airflow/sensors/base.py", line 264, in execute
    raise e
  File "/home/denys/airflow_venv/lib/python3.12/site-packages/airflow/sensors/base.py", line 246, in execute
    poke_return = self.poke(context)
                  ^^^^^^^^^^^^^^^^^^
  File "/home/denys/airflow_venv/lib/python3.12/site-packages/airflow/providers/http/sensors/http.py", line 158, in poke
    raise exc
  File "/home/denys/airflow_venv/lib/python3.12/site-packages/airflow/providers/http/sensors/http.py", line 139, in poke
    response = hook.run(
               ^^^^^^^^^
  File "/home/denys/airflow_venv/lib/python3.12/site-packages/airflow/providers/http/hooks/http.py", line 188, in run
    return self.run_and_check(session, prepped_request, extra_options)
           ^^^^^^^^^^^^^^^^^^^^^^^^^^^^^^^^^^^^^^^^^^^^^^^^^^^^^^^^^^^
  File "/home/denys/airflow_venv/lib/python3.12/site-packages/airflow/providers/http/hooks/http.py", line 239, in run_and_check
    self.check_response(response)
  File "/home/denys/airflow_venv/lib/python3.12/site-packages/airflow/providers/http/hooks/http.py", line 202, in check_response
    raise AirflowException(str(response.status_code) + ":" + response.reason)
airflow.exceptions.AirflowException: 401:Unauthorized
[2024-05-09T08:17:53.791+0000] {taskinstance.py:1206} INFO - Marking task as FAILED. dag_id=weather_dag, task_id=is_weater_api_ready, run_id=manual__2024-05-09T08:13:17.673871+00:00, execution_date=20240509T081317, start_date=20240509T081753, end_date=20240509T081753
[2024-05-09T08:17:53.866+0000] {standard_task_runner.py:110} ERROR - Failed to execute job 12 for task is_weater_api_ready (401:Unauthorized; 22850)
[2024-05-09T08:17:53.908+0000] {local_task_job_runner.py:240} INFO - Task exited with return code 1
[2024-05-09T08:17:53.952+0000] {taskinstance.py:3498} INFO - 0 downstream tasks scheduled from follow-on schedule check
[2024-05-09T08:17:53.953+0000] {local_task_job_runner.py:222} INFO - ::endgroup::
