[2024-05-09T09:16:11.212+0000] {local_task_job_runner.py:120} INFO - ::group::Pre task execution logs
[2024-05-09T09:16:11.225+0000] {taskinstance.py:2076} INFO - Dependencies all met for dep_context=non-requeueable deps ti=<TaskInstance: weather_dag.transform_load_weather_data manual__2024-05-09T09:13:35.288142+00:00 [queued]>
[2024-05-09T09:16:11.240+0000] {taskinstance.py:2076} INFO - Dependencies all met for dep_context=requeueable deps ti=<TaskInstance: weather_dag.transform_load_weather_data manual__2024-05-09T09:13:35.288142+00:00 [queued]>
[2024-05-09T09:16:11.241+0000] {taskinstance.py:2306} INFO - Starting attempt 2 of 3
[2024-05-09T09:16:11.305+0000] {taskinstance.py:2330} INFO - Executing <Task(PythonOperator): transform_load_weather_data> on 2024-05-09 09:13:35.288142+00:00
[2024-05-09T09:16:11.319+0000] {standard_task_runner.py:63} INFO - Started process 50196 to run task
[2024-05-09T09:16:11.336+0000] {standard_task_runner.py:90} INFO - Running: ['airflow', 'tasks', 'run', 'weather_dag', 'transform_load_weather_data', 'manual__2024-05-09T09:13:35.288142+00:00', '--job-id', '24', '--raw', '--subdir', 'DAGS_FOLDER/weather_dag.py', '--cfg-path', '/tmp/tmp0dsiq9na']
[2024-05-09T09:16:11.339+0000] {standard_task_runner.py:91} INFO - Job 24: Subtask transform_load_weather_data
[2024-05-09T09:16:11.450+0000] {task_command.py:426} INFO - Running <TaskInstance: weather_dag.transform_load_weather_data manual__2024-05-09T09:13:35.288142+00:00 [running]> on host ubuntu2204
[2024-05-09T09:16:11.632+0000] {taskinstance.py:2648} INFO - Exporting env vars: AIRFLOW_CTX_DAG_EMAIL='test@gmail.com' AIRFLOW_CTX_DAG_OWNER='airflow' AIRFLOW_CTX_DAG_ID='weather_dag' AIRFLOW_CTX_TASK_ID='transform_load_weather_data' AIRFLOW_CTX_EXECUTION_DATE='2024-05-09T09:13:35.288142+00:00' AIRFLOW_CTX_TRY_NUMBER='2' AIRFLOW_CTX_DAG_RUN_ID='manual__2024-05-09T09:13:35.288142+00:00'
[2024-05-09T09:16:11.639+0000] {taskinstance.py:430} INFO - ::endgroup::
[2024-05-09T09:16:11.662+0000] {taskinstance.py:441} INFO - ::group::Post task execution logs
[2024-05-09T09:16:11.663+0000] {taskinstance.py:2905} ERROR - Task failed with exception
Traceback (most recent call last):
  File "/home/denys/airflow_venv/lib/python3.12/site-packages/airflow/models/taskinstance.py", line 465, in _execute_task
    result = _execute_callable(context=context, **execute_callable_kwargs)
             ^^^^^^^^^^^^^^^^^^^^^^^^^^^^^^^^^^^^^^^^^^^^^^^^^^^^^^^^^^^^^
  File "/home/denys/airflow_venv/lib/python3.12/site-packages/airflow/models/taskinstance.py", line 432, in _execute_callable
    return execute_callable(context=context, **execute_callable_kwargs)
           ^^^^^^^^^^^^^^^^^^^^^^^^^^^^^^^^^^^^^^^^^^^^^^^^^^^^^^^^^^^^
  File "/home/denys/airflow_venv/lib/python3.12/site-packages/airflow/models/baseoperator.py", line 400, in wrapper
    return func(self, *args, **kwargs)
           ^^^^^^^^^^^^^^^^^^^^^^^^^^^
  File "/home/denys/airflow_venv/lib/python3.12/site-packages/airflow/operators/python.py", line 235, in execute
    return_value = self.execute_callable()
                   ^^^^^^^^^^^^^^^^^^^^^^^
  File "/home/denys/airflow_venv/lib/python3.12/site-packages/airflow/operators/python.py", line 252, in execute_callable
    return self.python_callable(*self.op_args, **self.op_kwargs)
           ^^^^^^^^^^^^^^^^^^^^^^^^^^^^^^^^^^^^^^^^^^^^^^^^^^^^^
  File "/home/denys/airflow/dags/weather_dag.py", line 21, in transform_load_data
    weather_description = data["weather"][0]["descriptioin"]
                          ~~~~~~~~~~~~~~~~~~^^^^^^^^^^^^^^^^
KeyError: 'descriptioin'
[2024-05-09T09:16:11.692+0000] {taskinstance.py:1206} INFO - Marking task as UP_FOR_RETRY. dag_id=weather_dag, task_id=transform_load_weather_data, run_id=manual__2024-05-09T09:13:35.288142+00:00, execution_date=20240509T091335, start_date=20240509T091611, end_date=20240509T091611
[2024-05-09T09:16:11.782+0000] {standard_task_runner.py:110} ERROR - Failed to execute job 24 for task transform_load_weather_data ('descriptioin'; 50196)
[2024-05-09T09:16:11.821+0000] {local_task_job_runner.py:240} INFO - Task exited with return code 1
[2024-05-09T09:16:11.844+0000] {taskinstance.py:3498} INFO - 0 downstream tasks scheduled from follow-on schedule check
[2024-05-09T09:16:11.845+0000] {local_task_job_runner.py:222} INFO - ::endgroup::
