[2024-05-23T09:07:29.721+0000] {local_task_job_runner.py:120} INFO - ::group::Pre task execution logs
[2024-05-23T09:07:29.752+0000] {taskinstance.py:2076} INFO - Dependencies all met for dep_context=non-requeueable deps ti=<TaskInstance: weather_dag_parallel.group_a.load_weather_data manual__2024-05-23T09:02:18.822413+00:00 [queued]>
[2024-05-23T09:07:29.763+0000] {taskinstance.py:2076} INFO - Dependencies all met for dep_context=requeueable deps ti=<TaskInstance: weather_dag_parallel.group_a.load_weather_data manual__2024-05-23T09:02:18.822413+00:00 [queued]>
[2024-05-23T09:07:29.764+0000] {taskinstance.py:2306} INFO - Starting attempt 3 of 3
[2024-05-23T09:07:29.831+0000] {taskinstance.py:2330} INFO - Executing <Task(PythonOperator): group_a.load_weather_data> on 2024-05-23 09:02:18.822413+00:00
[2024-05-23T09:07:29.836+0000] {standard_task_runner.py:63} INFO - Started process 35061 to run task
[2024-05-23T09:07:29.847+0000] {standard_task_runner.py:90} INFO - Running: ['airflow', 'tasks', 'run', 'weather_dag_parallel', 'group_a.load_weather_data', 'manual__2024-05-23T09:02:18.822413+00:00', '--job-id', '127', '--raw', '--subdir', 'DAGS_FOLDER/weatherapi_dag.py', '--cfg-path', '/tmp/tmpqa7cjvxb']
[2024-05-23T09:07:29.855+0000] {standard_task_runner.py:91} INFO - Job 127: Subtask group_a.load_weather_data
[2024-05-23T09:07:30.016+0000] {task_command.py:426} INFO - Running <TaskInstance: weather_dag_parallel.group_a.load_weather_data manual__2024-05-23T09:02:18.822413+00:00 [running]> on host ubuntu2204
[2024-05-23T09:07:30.211+0000] {taskinstance.py:2648} INFO - Exporting env vars: AIRFLOW_CTX_DAG_EMAIL='test@gmail.com' AIRFLOW_CTX_DAG_OWNER='airflow' AIRFLOW_CTX_DAG_ID='weather_dag_parallel' AIRFLOW_CTX_TASK_ID='group_a.load_weather_data' AIRFLOW_CTX_EXECUTION_DATE='2024-05-23T09:02:18.822413+00:00' AIRFLOW_CTX_TRY_NUMBER='3' AIRFLOW_CTX_DAG_RUN_ID='manual__2024-05-23T09:02:18.822413+00:00'
[2024-05-23T09:07:30.245+0000] {taskinstance.py:430} INFO - ::endgroup::
[2024-05-23T09:07:30.323+0000] {postgres.py:176} INFO - Running copy expert: COPY weather_data FROM stdin WITH DELIMETER AS ',', filename: current_weather_data_kyiv.csv
[2024-05-23T09:07:30.348+0000] {base.py:84} INFO - Using connection ID '***_conn' for task execution.
[2024-05-23T09:07:42.441+0000] {taskinstance.py:441} INFO - ::group::Post task execution logs
[2024-05-23T09:07:42.444+0000] {taskinstance.py:2905} ERROR - Task failed with exception
Traceback (most recent call last):
  File "/home/denys/airflow_venv/lib/python3.12/site-packages/airflow/models/taskinstance.py", line 465, in _execute_task
    result = _execute_callable(context=context, **execute_callable_kwargs)
             ^^^^^^^^^^^^^^^^^^^^^^^^^^^^^^^^^^^^^^^^^^^^^^^^^^^^^^^^^^^^^
  File "/home/denys/airflow_venv/lib/python3.12/site-packages/airflow/models/taskinstance.py", line 432, in _execute_callable
    return execute_callable(context=context, **execute_callable_kwargs)
           ^^^^^^^^^^^^^^^^^^^^^^^^^^^^^^^^^^^^^^^^^^^^^^^^^^^^^^^^^^^^
  File "/home/denys/airflow_venv/lib/python3.12/site-packages/airflow/models/baseoperator.py", line 400, in wrapper
    return func(self, *args, **kwargs)
           ^^^^^^^^^^^^^^^^^^^^^^^^^^^
  File "/home/denys/airflow_venv/lib/python3.12/site-packages/airflow/operators/python.py", line 235, in execute
    return_value = self.execute_callable()
                   ^^^^^^^^^^^^^^^^^^^^^^^
  File "/home/denys/airflow_venv/lib/python3.12/site-packages/airflow/operators/python.py", line 252, in execute_callable
    return self.python_callable(*self.op_args, **self.op_kwargs)
           ^^^^^^^^^^^^^^^^^^^^^^^^^^^^^^^^^^^^^^^^^^^^^^^^^^^^^
  File "/home/denys/airflow/dags/weatherapi_dag.py", line 61, in load_data
    hook.copy_expert(sql="COPY weather_data FROM stdin WITH DELIMETER AS ','",
  File "/home/denys/airflow_venv/lib/python3.12/site-packages/airflow/providers/postgres/hooks/postgres.py", line 181, in copy_expert
    with open(filename, "r+") as file, closing(self.get_conn()) as conn, closing(conn.cursor()) as cur:
                                               ^^^^^^^^^^^^^^^
  File "/home/denys/airflow_venv/lib/python3.12/site-packages/airflow/providers/postgres/hooks/postgres.py", line 162, in get_conn
    self.conn = psycopg2.connect(**conn_args)
                ^^^^^^^^^^^^^^^^^^^^^^^^^^^^^
  File "/home/denys/airflow_venv/lib/python3.12/site-packages/psycopg2/__init__.py", line 122, in connect
    conn = _connect(dsn, connection_factory=connection_factory, **kwasync)
           ^^^^^^^^^^^^^^^^^^^^^^^^^^^^^^^^^^^^^^^^^^^^^^^^^^^^^^^^^^^^^^^
psycopg2.OperationalError: could not translate host name "rds-***-test.c7yiag2mazhs.eu-north-1.rds.amazonaws.com" to address: Temporary failure in name resolution

[2024-05-23T09:07:42.478+0000] {taskinstance.py:1206} INFO - Marking task as FAILED. dag_id=weather_dag_parallel, task_id=group_a.load_weather_data, run_id=manual__2024-05-23T09:02:18.822413+00:00, execution_date=20240523T090218, start_date=20240523T090729, end_date=20240523T090742
[2024-05-23T09:07:42.577+0000] {standard_task_runner.py:110} ERROR - Failed to execute job 127 for task group_a.load_weather_data (could not translate host name "rds-***-test.c7yiag2mazhs.eu-north-1.rds.amazonaws.com" to address: Temporary failure in name resolution
; 35061)
[2024-05-23T09:07:42.627+0000] {local_task_job_runner.py:240} INFO - Task exited with return code 1
[2024-05-23T09:07:42.647+0000] {taskinstance.py:3498} INFO - 0 downstream tasks scheduled from follow-on schedule check
[2024-05-23T09:07:42.648+0000] {local_task_job_runner.py:222} INFO - ::endgroup::
