[2024-05-23T09:21:05.864+0000] {local_task_job_runner.py:120} INFO - ::group::Pre task execution logs
[2024-05-23T09:21:05.880+0000] {taskinstance.py:2076} INFO - Dependencies all met for dep_context=non-requeueable deps ti=<TaskInstance: weather_dag_parallel.group_a.load_weather_data manual__2024-05-23T09:02:18.822413+00:00 [queued]>
[2024-05-23T09:21:05.941+0000] {taskinstance.py:2076} INFO - Dependencies all met for dep_context=requeueable deps ti=<TaskInstance: weather_dag_parallel.group_a.load_weather_data manual__2024-05-23T09:02:18.822413+00:00 [queued]>
[2024-05-23T09:21:05.948+0000] {taskinstance.py:2306} INFO - Starting attempt 5 of 6
[2024-05-23T09:21:06.055+0000] {taskinstance.py:2330} INFO - Executing <Task(PythonOperator): group_a.load_weather_data> on 2024-05-23 09:02:18.822413+00:00
[2024-05-23T09:21:06.099+0000] {logging_mixin.py:188} WARNING - /home/denys/airflow_venv/lib/python3.12/site-packages/airflow/task/task_runner/standard_task_runner.py:61 DeprecationWarning: This process (pid=42540) is multi-threaded, use of fork() may lead to deadlocks in the child.
[2024-05-23T09:21:06.104+0000] {standard_task_runner.py:63} INFO - Started process 42885 to run task
[2024-05-23T09:21:06.120+0000] {standard_task_runner.py:90} INFO - Running: ['airflow', 'tasks', 'run', 'weather_dag_parallel', 'group_a.load_weather_data', 'manual__2024-05-23T09:02:18.822413+00:00', '--job-id', '129', '--raw', '--subdir', 'DAGS_FOLDER/weatherapi_dag.py', '--cfg-path', '/tmp/tmp1b8cqoo2']
[2024-05-23T09:21:06.125+0000] {standard_task_runner.py:91} INFO - Job 129: Subtask group_a.load_weather_data
[2024-05-23T09:21:06.279+0000] {task_command.py:426} INFO - Running <TaskInstance: weather_dag_parallel.group_a.load_weather_data manual__2024-05-23T09:02:18.822413+00:00 [running]> on host ubuntu2204
[2024-05-23T09:21:06.628+0000] {taskinstance.py:2648} INFO - Exporting env vars: AIRFLOW_CTX_DAG_EMAIL='test@gmail.com' AIRFLOW_CTX_DAG_OWNER='airflow' AIRFLOW_CTX_DAG_ID='weather_dag_parallel' AIRFLOW_CTX_TASK_ID='group_a.load_weather_data' AIRFLOW_CTX_EXECUTION_DATE='2024-05-23T09:02:18.822413+00:00' AIRFLOW_CTX_TRY_NUMBER='5' AIRFLOW_CTX_DAG_RUN_ID='manual__2024-05-23T09:02:18.822413+00:00'
[2024-05-23T09:21:06.639+0000] {taskinstance.py:430} INFO - ::endgroup::
[2024-05-23T09:21:06.893+0000] {postgres.py:176} INFO - Running copy expert: COPY weather_data FROM stdin WITH DELIMITER AS ',', filename: current_weather_data_kyiv.csv
[2024-05-23T09:21:06.952+0000] {base.py:84} INFO - Using connection ID '***_conn' for task execution.
[2024-05-23T09:21:07.670+0000] {taskinstance.py:441} INFO - ::group::Post task execution logs
[2024-05-23T09:21:07.680+0000] {taskinstance.py:2905} ERROR - Task failed with exception
Traceback (most recent call last):
  File "/home/denys/airflow_venv/lib/python3.12/site-packages/airflow/models/taskinstance.py", line 465, in _execute_task
    result = _execute_callable(context=context, **execute_callable_kwargs)
             ^^^^^^^^^^^^^^^^^^^^^^^^^^^^^^^^^^^^^^^^^^^^^^^^^^^^^^^^^^^^^
  File "/home/denys/airflow_venv/lib/python3.12/site-packages/airflow/models/taskinstance.py", line 432, in _execute_callable
    return execute_callable(context=context, **execute_callable_kwargs)
           ^^^^^^^^^^^^^^^^^^^^^^^^^^^^^^^^^^^^^^^^^^^^^^^^^^^^^^^^^^^^
  File "/home/denys/airflow_venv/lib/python3.12/site-packages/airflow/models/baseoperator.py", line 400, in wrapper
    return func(self, *args, **kwargs)
           ^^^^^^^^^^^^^^^^^^^^^^^^^^^
  File "/home/denys/airflow_venv/lib/python3.12/site-packages/airflow/operators/python.py", line 235, in execute
    return_value = self.execute_callable()
                   ^^^^^^^^^^^^^^^^^^^^^^^
  File "/home/denys/airflow_venv/lib/python3.12/site-packages/airflow/operators/python.py", line 252, in execute_callable
    return self.python_callable(*self.op_args, **self.op_kwargs)
           ^^^^^^^^^^^^^^^^^^^^^^^^^^^^^^^^^^^^^^^^^^^^^^^^^^^^^
  File "/home/denys/airflow/dags/weatherapi_dag.py", line 61, in load_data
    hook.copy_expert(sql="COPY weather_data FROM stdin WITH DELIMITER AS ','",
  File "/home/denys/airflow_venv/lib/python3.12/site-packages/airflow/providers/postgres/hooks/postgres.py", line 182, in copy_expert
    cur.copy_expert(sql, file)
psycopg2.errors.UndefinedTable: relation "weather_data" does not exist

[2024-05-23T09:21:07.727+0000] {taskinstance.py:1206} INFO - Marking task as UP_FOR_RETRY. dag_id=weather_dag_parallel, task_id=group_a.load_weather_data, run_id=manual__2024-05-23T09:02:18.822413+00:00, execution_date=20240523T090218, start_date=20240523T092105, end_date=20240523T092107
[2024-05-23T09:21:07.852+0000] {standard_task_runner.py:110} ERROR - Failed to execute job 129 for task group_a.load_weather_data (relation "weather_data" does not exist
; 42885)
[2024-05-23T09:21:07.893+0000] {local_task_job_runner.py:240} INFO - Task exited with return code 1
[2024-05-23T09:21:08.033+0000] {taskinstance.py:3498} INFO - 0 downstream tasks scheduled from follow-on schedule check
[2024-05-23T09:21:08.047+0000] {local_task_job_runner.py:222} INFO - ::endgroup::
