[2024-05-23T09:23:17.274+0000] {local_task_job_runner.py:120} INFO - ::group::Pre task execution logs
[2024-05-23T09:23:17.303+0000] {taskinstance.py:2076} INFO - Dependencies all met for dep_context=non-requeueable deps ti=<TaskInstance: weather_dag_parallel.group_a.load_weather_data manual__2024-05-23T09:02:18.822413+00:00 [queued]>
[2024-05-23T09:23:17.355+0000] {taskinstance.py:2076} INFO - Dependencies all met for dep_context=requeueable deps ti=<TaskInstance: weather_dag_parallel.group_a.load_weather_data manual__2024-05-23T09:02:18.822413+00:00 [queued]>
[2024-05-23T09:23:17.356+0000] {taskinstance.py:2306} INFO - Starting attempt 6 of 6
[2024-05-23T09:23:17.469+0000] {taskinstance.py:2330} INFO - Executing <Task(PythonOperator): group_a.load_weather_data> on 2024-05-23 09:02:18.822413+00:00
[2024-05-23T09:23:17.490+0000] {standard_task_runner.py:63} INFO - Started process 44632 to run task
[2024-05-23T09:23:17.502+0000] {standard_task_runner.py:90} INFO - Running: ['airflow', 'tasks', 'run', 'weather_dag_parallel', 'group_a.load_weather_data', 'manual__2024-05-23T09:02:18.822413+00:00', '--job-id', '130', '--raw', '--subdir', 'DAGS_FOLDER/weatherapi_dag.py', '--cfg-path', '/tmp/tmpdte89wxj']
[2024-05-23T09:23:17.544+0000] {standard_task_runner.py:91} INFO - Job 130: Subtask group_a.load_weather_data
[2024-05-23T09:23:17.714+0000] {task_command.py:426} INFO - Running <TaskInstance: weather_dag_parallel.group_a.load_weather_data manual__2024-05-23T09:02:18.822413+00:00 [running]> on host ubuntu2204
[2024-05-23T09:23:17.925+0000] {taskinstance.py:2648} INFO - Exporting env vars: AIRFLOW_CTX_DAG_EMAIL='test@gmail.com' AIRFLOW_CTX_DAG_OWNER='airflow' AIRFLOW_CTX_DAG_ID='weather_dag_parallel' AIRFLOW_CTX_TASK_ID='group_a.load_weather_data' AIRFLOW_CTX_EXECUTION_DATE='2024-05-23T09:02:18.822413+00:00' AIRFLOW_CTX_TRY_NUMBER='6' AIRFLOW_CTX_DAG_RUN_ID='manual__2024-05-23T09:02:18.822413+00:00'
[2024-05-23T09:23:17.926+0000] {taskinstance.py:430} INFO - ::endgroup::
[2024-05-23T09:23:18.017+0000] {postgres.py:176} INFO - Running copy expert: COPY weather_data FROM stdin WITH DELIMITER AS ',', filename: current_weather_data_kyiv.csv
[2024-05-23T09:23:18.045+0000] {base.py:84} INFO - Using connection ID '***_conn' for task execution.
[2024-05-23T09:23:18.816+0000] {taskinstance.py:441} INFO - ::group::Post task execution logs
[2024-05-23T09:23:18.834+0000] {taskinstance.py:2905} ERROR - Task failed with exception
Traceback (most recent call last):
  File "/home/denys/airflow_venv/lib/python3.12/site-packages/airflow/models/taskinstance.py", line 465, in _execute_task
    result = _execute_callable(context=context, **execute_callable_kwargs)
             ^^^^^^^^^^^^^^^^^^^^^^^^^^^^^^^^^^^^^^^^^^^^^^^^^^^^^^^^^^^^^
  File "/home/denys/airflow_venv/lib/python3.12/site-packages/airflow/models/taskinstance.py", line 432, in _execute_callable
    return execute_callable(context=context, **execute_callable_kwargs)
           ^^^^^^^^^^^^^^^^^^^^^^^^^^^^^^^^^^^^^^^^^^^^^^^^^^^^^^^^^^^^
  File "/home/denys/airflow_venv/lib/python3.12/site-packages/airflow/models/baseoperator.py", line 400, in wrapper
    return func(self, *args, **kwargs)
           ^^^^^^^^^^^^^^^^^^^^^^^^^^^
  File "/home/denys/airflow_venv/lib/python3.12/site-packages/airflow/operators/python.py", line 235, in execute
    return_value = self.execute_callable()
                   ^^^^^^^^^^^^^^^^^^^^^^^
  File "/home/denys/airflow_venv/lib/python3.12/site-packages/airflow/operators/python.py", line 252, in execute_callable
    return self.python_callable(*self.op_args, **self.op_kwargs)
           ^^^^^^^^^^^^^^^^^^^^^^^^^^^^^^^^^^^^^^^^^^^^^^^^^^^^^
  File "/home/denys/airflow/dags/weatherapi_dag.py", line 61, in load_data
    hook.copy_expert(sql="COPY weather_data FROM stdin WITH DELIMITER AS ','",
  File "/home/denys/airflow_venv/lib/python3.12/site-packages/airflow/providers/postgres/hooks/postgres.py", line 182, in copy_expert
    cur.copy_expert(sql, file)
psycopg2.errors.UndefinedTable: relation "weather_data" does not exist

[2024-05-23T09:23:18.922+0000] {taskinstance.py:1206} INFO - Marking task as FAILED. dag_id=weather_dag_parallel, task_id=group_a.load_weather_data, run_id=manual__2024-05-23T09:02:18.822413+00:00, execution_date=20240523T090218, start_date=20240523T092317, end_date=20240523T092318
[2024-05-23T09:23:19.097+0000] {standard_task_runner.py:110} ERROR - Failed to execute job 130 for task group_a.load_weather_data (relation "weather_data" does not exist
; 44632)
[2024-05-23T09:23:19.206+0000] {local_task_job_runner.py:240} INFO - Task exited with return code 1
[2024-05-23T09:23:19.432+0000] {taskinstance.py:3498} INFO - 0 downstream tasks scheduled from follow-on schedule check
[2024-05-23T09:23:19.453+0000] {local_task_job_runner.py:222} INFO - ::endgroup::
